Workbook
Name Slicer_Platform: #N/A
Name Slicer_Platform1: #N/A

Sheet Post
A1: PostID | B1: Platform | C1: Date | D1: ContentType | E1: Hashtags | F1: Likes | G1: Shares | H1: Comments | I1: Clicks | J1: Reach | K1: Impressions | L1: Engagement Rate | M1: Campaign
A2: A234 | B2: LinkedIn | C2: 45444 | D2: Image | E2: #AppleMusic,#AppleLifestyle | F2: 19844 | G2: 1022 | H2: 860 | I2: 2570 | J2: 23719 | K2: 182628 | L2: 0.11896314 | M2: Sustainability Awareness Drive
A3: A220 | B3: YouTube | C3: 45445 | D3: Video | E3: #MacBookAirM3,#AppleInnovation | F3: 14199 | G3: 1206 | H3: 954 | I3: 2009 | J3: 8 | K3: 65537 | L3: 0.24961472 | M3: Sustainability Awareness Drive
A4: A90 | B4: Twitter | C4: 45446 | D4: Image | E4: #AppleEvent,#iPhone16 | F4: 8941 | G4: 911 | H4: 166 | I4: 1217 | J4: 68817 | K4: 221180 | L4: 0.045293426 | M4: MacBook Air M3 Campaign
A5: A146 | B5: YouTube | C5: 45448 | D5: Tweet | E5: #iPhonePhotography,#ShotOniPhone | F5: 18907 | G5: 1075 | H5: 675 | I5: 1383 | J5: 17875 | K5: 186649 | L5: 0.11067297 | M5: Apple Watch Ultra 2 Launch
A6: A87 | B6: Twitter | C6: 45449 | D6: Tweet | E6: #iPhone16Launch,#AppleEvent | F6: 11521 | G6: 1071 | H6: 762 | I6: 2539 | J6: 12701 | K6: 238350 | L6: 0.056026851 | M6: Sustainability Awareness Drive
A7: A188 | B7: YouTube | C7: 45449 | D7: Carousel | E7: #Sustainability,#AppleEarth | F7: 3531 | G7: 789 | H7: 467 | I7: 1867 | J7: 40816 | K7: 236037 | L7: 0.020280719 | M7: Sustainability Awareness Drive
A8: A276 | B8: LinkedIn | C8: 45450 | D8: Video | E8: #AppleEvent,#iPadPro | F8: 8233 | G8: 436 | H8: 269 | I8: 2037 | J8: 8875 | K8: 52289 | L8: 0.17093461 | M8: Apple Watch Ultra 2 Launch
A9: A98 | B9: LinkedIn | C9: 45453 | D9: Video | E9: #AppleMusic,#AppleLifestyle | F9: 21561 | G9: 340 | H9: 741 | I9: 986 | J9: 24826 | K9: 198492 | L9: 0.11407009 | M9: Apple Watch Ultra 2 Launch
A10: A218 | B10: Instagram | C10: 45454 | D10: Video | E10: #MacBookProM3 | F10: 14910 | G10: 778 | H10: 289 | I10: 2541 | J10: 14309 | K10: 247815 | L10: 0.064471481 | M10: Sustainability Awareness Drive
A11: A227 | B11: Instagram | C11: 45455 | D11: Tweet | E11: #MacBookAirM3,#AppleInnovation | F11: 17679 | G11: 690 | H11: 451 | I11: 2195 | J11: 4390 | K11: 235804 | L11: 0.079812047 | M11: MacBook Air M3 Campaign
A12: A51 | B12: YouTube | C12: 45456 | D12: Carousel | E12: #AppleWatch,#Health | F12: 23164 | G12: 1122 | H12: 900 | I12: 888 | J12: 36938 | K12: 104674 | L12: 0.24061371 | M12: Apple Watch Ultra 2 Launch
A13: A80 | B13: LinkedIn | C13: 45456 | D13: Image | E13: #AppleWatchUltra2,#HealthTech | F13: 14173 | G13: 294 | H13: 257 | I13: 1288 | J13: 39466 | K13: 55563 | L13: 0.26499649 | M13: MacBook Air M3 Campaign
... A301: A192 | B301: YouTube | C301: 45945 | D301: Image | E301: #AppleWatch,#Health | F301: 8882 | G301: 701 | H301: 421 | I301: 2343 | J301: 13588 | K301: 139304 | L301: 0.071814162 | M301: Apple Event September 2025

Sheet Engagement
A1: Week_Start_Date | B1: Platform | C1: New_Followers | D1: Unfollows | E1: Total_Followers | F1: Follower Growth Rate | G1: Engagement_Rate | H1: Ad_Spend
A2: 45446 | B2: Instagram | C2: 4138 | D2: 361 | E2: 103777 | F2: 0.036395348 | G2: 56.637791 | H2: 23944
A3: 45446 | B3: Twitter | C3: 8693 | D3: 1261 | E3: 111209 | F3: 0.066829124 | G3: 69.475492 | H3: 29873
A4: 45446 | B4: YouTube | C4: 9264 | D4: 1141 | E4: 119332 | F4: 0.068070593 | G4: 92.312205 | H4: 50372
A5: 45446 | B5: YouTube | C5: 8842 | D5: 971 | E5: 127203 | F5: 0.061877471 | G5: 16.351816 | H5: 33928
A6: 45453 | B6: Instagram | C6: 7721 | D6: 506 | E6: 134418 | F6: 0.053675847 | G6: 35.577824 | H6: 25379
A7: 45453 | B7: YouTube | C7: 8002 | D7: 524 | E7: 141896 | F7: 0.052700569 | G7: 52.064893 | H7: 46751
A8: 45453 | B8: Twitter | C8: 5225 | D8: 291 | E8: 146830 | F8: 0.033603487 | G8: 19.551863 | H8: 44546
A9: 45453 | B9: Twitter | C9: 3978 | D9: 543 | E9: 150265 | F9: 0.022859615 | G9: 49.159818 | H9: 34286
A10: 45460 | B10: Instagram | C10: 8373 | D10: 921 | E10: 157717 | F10: 0.047249187 | G10: 12.226329 | H10: 15110
A11: 45460 | B11: Twitter | C11: 6907 | D11: 834 | E11: 163790 | F11: 0.037077966 | G11: 54.158984 | H11: 22087
A12: 45460 | B12: LinkedIn | C12: 7097 | D12: 369 | E12: 170518 | F12: 0.039456245 | G12: 9.2506363 | H12: 33762
A13: 45460 | B13: Instagram | C13: 6656 | D13: 978 | E13: 176196 | F13: 0.032225476 | G13: 60.425889 | H13: 27081
... A201: 45789 | B201: Twitter | C201: 8527 | D201: 1091 | E201: 1186398 | F201: 0.0062677112 | G201: 1.6760817 | H201: 41703

Sheet Campaign
A1: Campaign_Name | B1: Start_Date | C1: End_Date | D1: Objective | E1: Ad_Spend | F1: Impressions | G1: Engagement_Uplift
A2: iPhone 16 Launch | B2: 45458 | C2: 45488 | D2: Product Launch | E2: 85000 | F2: 950000 | G2: 0.45
A3: MacBook Air M3 Campaign | B3: 45566 | C3: 45596 | D3: Product Promotion | E3: 60000 | F3: 780000 | G3: 0.38
A4: Apple Watch Ultra 2 Launch | B4: 45651 | C4: 45667 | D4: Health & Fitness Awareness | E4: 55000 | F4: 700000 | G4: 0.41
A5: Sustainability Awareness Drive | B5: 45717 | C5: 45747 | D5: Sustainability Branding | E5: 40000 | F5: 550000 | G5: 0.32
A6: Apple Event September 2025 | B6: 45901 | C6: 45930 | D6: Brand Engagement | E6: 75000 | F6: 880000 | G6: 0.47

Sheet Task 6.1
B3: Sum of Total_Followers | C3: Column Labels | I3: Task 6: Follower Retention & Loyalty
B4: Row Labels | C4: Instagram | D4: LinkedIn | E4: Twitter | F4: YouTube | G4: Grand Total
B5: 45446 | C5: 103777 | E5: 111209 | F5: 246535 | G5: 461521 | I5: 6.1) Visualize weekly follower growth per platform (line chart).
B6: 45453 | C6: 134418 | E6: 297095 | F6: 141896 | G6: 573409
B7: 45460 | C7: 333913 | D7: 170518 | E7: 163790 | G7: 668221 | I7: Using Engagement Dataset
B8: 45467 | C8: 189735 | E8: 389668 | F8: 198388 | G8: 777791 | I8: Pivot Table --> Platform in column --> week start date in rows -->
B9: 45474 | C9: 446576 | D9: 210260 | E9: 218723 | G9: 875559 | I9: Total followers in values --> sum
B10: 45481 | D10: 716856 | E10: 231802 | G10: 948658 | I10: insert --> line chart --> stacked line -->
B11: 45488 | C11: 503831 | E11: 253858 | F11: 255684 | G11: 1013373 | I11: Chart element --> select axis titles , chart title, grindlines -->
B12: 45495 | D12: 544695 | E12: 272227 | F12: 289283 | G12: 1106205
B13: 45502 | D13: 587844 | E13: 306304 | F13: 300265 | G13: 1194413
B14: 45509 | C14: 309517 | D14: 320404 | E14: 313014 | F14: 315557 | G14: 1258492
B15: 45516 | C15: 333052 | E15: 673289 | F15: 340085 | G15: 1346426
B16: 45523 | C16: 720006 | F16: 729433 | G16: 1449439
B17: 45530 | C17: 385849 | D17: 371865 | E17: 377618 | F17: 391152 | G17: 1526484
B18: 45537 | C18: 795220 | D18: 413369 | E18: 405141 | G18: 1613730
B19: 45544 | C19: 420811 | D19: 438545 | F19: 862353 | G19: 1721709
B20: 45551 | D20: 447968 | E20: 453977 | F20: 895821 | G20: 1797766
B21: 45558 | C21: 1391500 | E21: 460228 | G21: 1851728
B22: 45565 | C22: 967881 | E22: 976411 | G22: 1944292
B23: 45572 | C23: 507970 | D23: 492814 | F23: 1002177 | G23: 2002961
B24: 45579 | E24: 1572941 | F24: 522852 | G24: 2095793
B25: 45586 | C25: 1654883 | F25: 545824 | G25: 2200707
B26: 45593 | D26: 1170612 | F26: 1143345 | G26: 2313957
B27: 45600 | D27: 604702 | E27: 1202875 | F27: 599760 | G27: 2407337
B28: 45607 | D28: 620702 | E28: 1223008 | F28: 625922 | G28: 2469632
B29: 45614 | C29: 631128 | D29: 1287851 | E29: 637512 | G29: 2556491
B30: 45621 | C30: 1317342 | D30: 670642 | F30: 675785 | G30: 2663769
B31: 45628 | C31: 1367340 | D31: 682556 | F31: 694115 | G31: 2744011
B32: 45635 | C32: 704218 | D32: 709957 | E32: 700757 | F32: 709008 | G32: 2823940
B33: 45642 | C33: 1428308 | D33: 723286 | E33: 729561 | G33: 2881155
B34: 45649 | C34: 735242 | D34: 1472344 | F34: 748744 | G34: 2956330
B35: 45656 | C35: 761158 | D35: 1526479 | E35: 772614 | G35: 3060251
B36: 45663 | D36: 781868 | E36: 1589207 | F36: 798137 | G36: 3169212
B37: 45670 | C37: 810061 | D37: 807142 | E37: 817407 | F37: 818408 | G37: 3253018
B38: 45677 | E38: 2499836 | F38: 846217 | G38: 3346053
B39: 45684 | C39: 868909 | D39: 853477 | E39: 1725104 | G39: 3447490
B40: 45691 | E40: 1778284 | F40: 1762198 | G40: 3540482
B41: 45698 | D41: 2715333 | E41: 904407 | G41: 3619740
B42: 45705 | C42: 1851857 | D42: 917475 | E42: 912374 | G42: 3681706
...

Sheet Task 6.2
B2: Row Labels | C2: Sum of Net_Follower_Gain
B3: 45495 | C3: 32218 | F3: Task 6: Follower Retention & Loyalty
B4: 45586 | C4: 30891
B5: 45712 | C5: 30446 | F5: 6.2) Identify the peak week of follower gain.
B6: 45621 | C6: 28625
B7: 45467 | C7: 28622 | F7: Using Engagement Dataset
B8: 45691 | C8: 28533 | F8: Pivot table -->
B9: 45733 | C9: 28020 | F9: Drag Week start date to rows -->
B10: 45677 | C10: 27809
B11: 45593 | C11: 27254 | F11: Now to create new column of net follower gains :-
B12: 45446 | C12: 27203 | F12: Pivot table analyze --> field, tems, sets --> calculated field -->
B13: 45663 | C13: 27057 | F13: Net follwers gain = new followers- unfollows -->
B14: 45516 | C14: 26686
B15: 45460 | C15: 25931 | F15: Drag Net follower gain to values --> sum
B16: 45740 | C16: 25416 | F16: Sort Net follower gain --> largest to smallest
B17: 45544 | C17: 25176 | F17: value filter --> top 1
B18: 45761 | C18: 24995
B19: 45656 | C19: 23870
B20: 45579 | C20: 23371
B21: 45523 | C21: 23262
B22: 45453 | C22: 23062
B23: 45684 | C23: 22692
B24: 45537 | C24: 22217
B25: 45768 | C25: 22070
B26: 45614 | C26: 21238
B27: 45530 | C27: 20800
B28: 45754 | C28: 20720
B29: 45719 | C29: 20389
... B52: 45698 | C52: 13642

Sheet Insta
A1: Week_Start_Date | B1: Platform | C1: New_Followers | D1: Unfollows | E1: Total_Followers | F1: Net Followers Gain | G1: Follower Growth Rate | H1: Engagement_Rate | I1: Ad_Spend | K1: Week_Start_Date | L1: Platform | M1: Net Followers Gain | Z1: Week_Start_Date | AA1: Column1 | AB1: Total_Followers
A2: 45446 | B2: Instagram | C2: 4138 | D2: 361 | E2: 103777 | F2: =Insta!$C2-Insta!$D2 -> 3777 | G2: 0.036395348 | H2: 56.637791 | I2: 23944 | K2: 45446 | M2: 3777 | Z2: 45446 | AB2: 103777
A3: 45446 | B3: Twitter | C3: 8693 | D3: 1261 | E3: 111209 | F3: =Insta!$C3-Insta!$D3 -> 7432 | G3: 0.066829124 | H3: 69.475492 | I3: 29873 | K3: 45446 | L3: Twitter | M3: 7432 | Z3: 45446 | AB3: 111209
A4: 45446 | B4: YouTube | C4: 9264 | D4: 1141 | E4: 119332 | F4: =Insta!$C4-Insta!$D4 -> 8123 | G4: 0.068070593 | H4: 92.312205 | I4: 50372 | K4: 45446 | L4: YouTube | M4: 8123 | Z4: 45446 | AB4: 119332
A5: 45446 | B5: YouTube | C5: 8842 | D5: 971 | E5: 127203 | F5: =Insta!$C5-Insta!$D5 -> 7871 | G5: 0.061877471 | H5: 16.351816 | I5: 33928 | K5: 45446 | L5: YouTube | M5: 7871 | Z5: 45446 | AB5: 127203
A6: 45453 | B6: Instagram | C6: 7721 | D6: 506 | E6: 134418 | F6: =Insta!$C6-Insta!$D6 -> 7215 | G6: 0.053675847 | H6: 35.577824 | I6: 25379 | K6: 45453 | M6: 7215 | Z6: 45453 | AB6: 134418
A7: 45453 | B7: YouTube | C7: 8002 | D7: 524 | E7: 141896 | F7: =Insta!$C7-Insta!$D7 -> 7478 | G7: 0.052700569 | H7: 52.064893 | I7: 46751 | K7: 45453 | L7: YouTube | M7: 7478 | Z7: 45453 | AB7: 141896
A8: 45453 | B8: Twitter | C8: 5225 | D8: 291 | E8: 146830 | F8: =Insta!$C8-Insta!$D8 -> 4934 | G8: 0.033603487 | H8: 19.551863 | I8: 44546 | K8: 45453 | L8: Twitter | M8: 4934 | Z8: 45453 | AB8: 146830
A9: 45453 | B9: Twitter | C9: 3978 | D9: 543 | E9: 150265 | F9: =Insta!$C9-Insta!$D9 -> 3435 | G9: 0.022859615 | H9: 49.159818 | I9: 34286 | K9: 45453 | L9: Twitter | M9: 3435 | Z9: 45453 | AB9: 150265
A10: 45460 | B10: Instagram | C10: 8373 | D10: 921 | E10: 157717 | F10: =Insta!$C10-Insta!$D10 -> 7452 | G10: 0.047249187 | H10: 12.226329 | I10: 15110 | K10: 45460 | M10: 7452 | Z10: 45460 | AB10: 157717
A11: 45460 | B11: Twitter | C11: 6907 | D11: 834 | E11: 163790 | F11: =Insta!$C11-Insta!$D11 -> 6073 | G11: 0.037077966 | H11: 54.158984 | I11: 22087 | K11: 45460 | L11: Twitter | M11: 6073 | Z11: 45460 | AB11: 163790
A12: 45460 | B12: LinkedIn | C12: 7097 | D12: 369 | E12: 170518 | F12: =Insta!$C12-Insta!$D12 -> 6728 | G12: 0.039456245 | H12: 9.2506363 | I12: 33762 | K12: 45460 | L12: LinkedIn | M12: 6728 | Z12: 45460 | AB12: 170518
A13: 45460 | B13: Instagram | C13: 6656 | D13: 978 | E13: 176196 | F13: =Insta!$C13-Insta!$D13 -> 5678 | G13: 0.032225476 | H13: 60.425889 | I13: 27081 | K13: 45460 | M13: 5678 | Z13: 45460 | AB13: 176196
A14: 45467 | B14: Twitter | C14: 9984 | D14: 1330 | E14: 184850 | F14: =Insta!$C14-Insta!$D14 -> 8654 | G14: 0.046816338 | H14: 57.524479 | I14: 44947 | K14: 45467 | L14: Twitter | M14: 8654 | Z14: 45467 | AB14: 184850
A15: 45467 | B15: Instagram | C15: 5259 | D15: 374 | E15: 189735 | F15: =Insta!$C15-Insta!$D15 -> 4885 | G15: 0.025746436 | H15: 14.827523 | I15: 19596 | K15: 45467 | M15: 4885 | Z15: 45467 | AB15: 189735
A16: 45467 | B16: YouTube | C16: 9286 | D16: 633 | E16: 198388 | F16: =Insta!$C16-Insta!$D16 -> 8653 | G16: 0.043616549 | H16: 5.4343005 | I16: 48019 | K16: 45467 | L16: YouTube | M16: 8653 | Z16: 45467 | AB16: 198388
A17: 45467 | B17: Twitter | C17: 6901 | D17: 471 | E17: 204818 | F17: =Insta!$C17-Insta!$D17 -> 6430 | G17: 0.031393725 | H17: 60.827662 | I17: 52003 | K17: 45467 | L17: Twitter | M17: 6430 | Z17: 45467 | AB17: 204818
A18: 45474 | B18: LinkedIn | C18: 5917 | D18: 475 | E18: 210260 | F18: =Insta!$C18-Insta!$D18 -> 5442 | G18: 0.025882241 | H18: 17.894036 | I18: 28313 | K18: 45474 | L18: LinkedIn | M18: 5442 | Z18: 45474 | AB18: 210260
A19: 45474 | B19: Twitter | C19: 9429 | D19: 966 | E19: 218723 | F19: =Insta!$C19-Insta!$D19 -> 8463 | G19: 0.038692776 | H19: 7.6914636 | I19: 57639 | K19: 45474 | L19: Twitter | M19: 8463 | Z19: 45474 | AB19: 218723
A20: 45474 | B20: Instagram | C20: 3530 | D20: 328 | E20: 221925 | F20: =Insta!$C20-Insta!$D20 -> 3202 | G20: 0.014428298 | H20: 12.83722 | I20: 11013 | K20: 45474 | M20: 3202 | Z20: 45474 | AB20: 221925
A21: 45474 | B21: Instagram | C21: 2960 | D21: 234 | E21: 224651 | F21: =Insta!$C21-Insta!$D21 -> 2726 | G21: 0.012134377 | H21: 17.412787 | I21: 59378 | K21: 45474 | M21: 2726 | Z21: 45474 | AB21: 224651
A22: 45481 | B22: Twitter | C22: 8045 | D22: 894 | E22: 231802 | F22: =Insta!$C22-Insta!$D22 -> 7151 | G22: 0.030849604 | H22: 47.634188 | I22: 33705 | K22: 45481 | L22: Twitter | M22: 7151 | Z22: 45481 | AB22: 231802
A23: 45481 | B23: LinkedIn | C23: 2048 | D23: 130 | E23: 233720 | F23: =Insta!$C23-Insta!$D23 -> 1918 | G23: 0.0082064008 | H23: 39.284614 | I23: 11828 | K23: 45481 | L23: LinkedIn | M23: 1918 | Z23: 45481 | AB23: 233720
A24: 45481 | B24: LinkedIn | C24: 6772 | D24: 536 | E24: 239956 | F24: =Insta!$C24-Insta!$D24 -> 6236 | G24: 0.025988098 | H24: 9.8205504 | I24: 17909 | K24: 45481 | L24: LinkedIn | M24: 6236 | Z24: 45481 | AB24: 239956
A25: 45481 | B25: LinkedIn | C25: 3529 | D25: 305 | E25: 243180 | F25: =Insta!$C25-Insta!$D25 -> 3224 | G25: 0.013257669 | H25: 41.606629 | I25: 48356 | K25: 45481 | L25: LinkedIn | M25: 3224 | Z25: 45481 | AB25: 243180
A26: 45488 | B26: Instagram | C26: 3964 | D26: 378 | E26: 246766 | F26: =Insta!$C26-Insta!$D26 -> 3586 | G26: 0.014531986 | H26: 13.63559 | I26: 23109 | K26: 45488 | M26: 3586 | Z26: 45488 | AB26: 246766
A27: 45488 | B27: Twitter | C27: 8137 | D27: 1045 | E27: 253858 | F27: =Insta!$C27-Insta!$D27 -> 7092 | G27: 0.027936878 | H27: 20.472469 | I27: 12023 | K27: 45488 | L27: Twitter | M27: 7092 | Z27: 45488 | AB27: 253858
A28: 45488 | B28: YouTube | C28: 1963 | D28: 137 | E28: 255684 | F28: =Insta!$C28-Insta!$D28 -> 1826 | G28: 0.0071416279 | H28: 11.208367 | I28: 24537 | K28: 45488 | L28: YouTube | M28: 1826 | Z28: 45488 | AB28: 255684
A29: 45488 | B29: Instagram | C29: 1536 | D29: 155 | E29: 257065 | F29: =Insta!$C29-Insta!$D29 -> 1381 | G29: 0.0053721821 | H29: 12.157626 | I29: 36661 | K29: 45488 | M29: 1381 | Z29: 45488 | AB29: 257065
A30: 45495 | B30: LinkedIn | C30: 8340 | D30: 911 | E30: 264494 | F30: =Insta!$C30-Insta!$D30 -> 7429 | G30: 0.028087594 | H30: 37.302926 | I30: 48659 | K30: 45495 | L30: LinkedIn | M30: 7429 | Z30: 45495 | AB30: 264494
A31: 45495 | B31: Twitter | C31: 8179 | D31: 446 | E31: 272227 | F31: =Insta!$C31-Insta!$D31 -> 7733 | G31: 0.02840644 | H31: 41.821715 | I31: 43848 | K31: 45495 | L31: Twitter | M31: 7733 | Z31: 45495 | AB31: 272227
A32: 45495 | B32: LinkedIn | C32: 8967 | D32: 993 | E32: 280201 | F32: =Insta!$C32-Insta!$D32 -> 7974 | G32: 0.028458143 | H32: 52.792103 | I32: 47804 | K32: 45495 | L32: LinkedIn | M32: 7974 | Z32: 45495 | AB32: 280201
A33: 45495 | B33: YouTube | C33: 9734 | D33: 652 | E33: 289283 | F33: =Insta!$C33-Insta!$D33 -> 9082 | G33: 0.031394862 | H33: 49.647923 | I33: 25379 | K33: 45495 | L33: YouTube | M33: 9082 | Z33: 45495 | AB33: 289283
A34: 45502 | B34: LinkedIn | C34: 1845 | D34: 104 | E34: 291024 | F34: =Insta!$C34-Insta!$D34 -> 1741 | G34: 0.0059823245 | H34: 28.158159 | I34: 37766 | K34: 45502 | L34: LinkedIn | M34: 1741 | Z34: 45502 | AB34: 291024
A35: 45502 | B35: LinkedIn | C35: 6777 | D35: 981 | E35: 296820 | F35: =Insta!$C35-Insta!$D35 -> 5796 | G35: 0.019526986 | H35: 23.920558 | I35: 53590 | K35: 45502 | L35: LinkedIn | M35: 5796 | Z35: 45502 | AB35: 296820
A36: 45502 | B36: YouTube | C36: 4036 | D36: 591 | E36: 300265 | F36: =Insta!$C36-Insta!$D36 -> 3445 | G36: 0.011473199 | H36: 44.219273 | I36: 12563 | K36: 45502 | L36: YouTube | M36: 3445 | Z36: 45502 | AB36: 300265
A37: 45502 | B37: Twitter | C37: 6947 | D37: 908 | E37: 306304 | F37: =Insta!$C37-Insta!$D37 -> 6039 | G37: 0.019715707 | H37: 14.117674 | I37: 46060 | K37: 45502 | L37: Twitter | M37: 6039 | Z37: 45502 | AB37: 306304
A38: 45509 | B38: Instagram | C38: 3494 | D38: 281 | E38: 309517 | F38: =Insta!$C38-Insta!$D38 -> 3213 | G38: 0.01038069 | H38: 27.765519 | I38: 39197 | K38: 45509 | M38: 3213 | Z38: 45509 | AB38: 309517
A39: 45509 | B39: Twitter | C39: 3719 | D39: 222 | E39: 313014 | F39: =Insta!$C39-Insta!$D39 -> 3497 | G39: 0.011172024 | H39: 21.669318 | I39: 13586 | K39: 45509 | L39: Twitter | M39: 3497 | Z39: 45509 | AB39: 313014
A40: 45509 | B40: YouTube | C40: 2884 | D40: 341 | E40: 315557 | F40: =Insta!$C40-Insta!$D40 -> 2543 | G40: 0.0080587659 | H40: 46.99975 | I40: 26087 | K40: 45509 | L40: YouTube | M40: 2543 | Z40: 45509 | AB40: 315557
...

Sheet Twitter
A1: Week_Start_Date | B1: Platform | C1: New_Followers | D1: Unfollows | E1: Total_Followers | F1: Net Followers Gain | G1: Follower Growth Rate | H1: Engagement_Rate | I1: Ad_Spend | K1: Week_Start_Date | L1: Column1 | M1: Net Followers Gain | X1: Week_Start_Date | Y1: Column1 | Z1: Total_Followers
A2: 45446 | B2: Instagram | C2: 4138 | D2: 361 | E2: 103777 | F2: =Twitter!$C2-Twitter!$D2 -> 3777 | G2: 0.036395348 | H2: 56.637791 | I2: 23944 | K2: 45446 | L2: Instagram | M2: 3777 | X2: 45446 | Z2: 103777
A3: 45446 | B3: Twitter | C3: 8693 | D3: 1261 | E3: 111209 | F3: =Twitter!$C3-Twitter!$D3 -> 7432 | G3: 0.066829124 | H3: 69.475492 | I3: 29873 | K3: 45446 | M3: 7432 | X3: 45446 | Z3: 111209
A4: 45446 | B4: YouTube | C4: 9264 | D4: 1141 | E4: 119332 | F4: =Twitter!$C4-Twitter!$D4 -> 8123 | G4: 0.068070593 | H4: 92.312205 | I4: 50372 | K4: 45446 | L4: YouTube | M4: 8123 | X4: 45446 | Z4: 119332
A5: 45446 | B5: YouTube | C5: 8842 | D5: 971 | E5: 127203 | F5: =Twitter!$C5-Twitter!$D5 -> 7871 | G5: 0.061877471 | H5: 16.351816 | I5: 33928 | K5: 45446 | L5: YouTube | M5: 7871 | X5: 45446 | Z5: 127203
A6: 45453 | B6: Instagram | C6: 7721 | D6: 506 | E6: 134418 | F6: =Twitter!$C6-Twitter!$D6 -> 7215 | G6: 0.053675847 | H6: 35.577824 | I6: 25379 | K6: 45453 | L6: Instagram | M6: 7215 | X6: 45453 | Z6: 134418
A7: 45453 | B7: YouTube | C7: 8002 | D7: 524 | E7: 141896 | F7: =Twitter!$C7-Twitter!$D7 -> 7478 | G7: 0.052700569 | H7: 52.064893 | I7: 46751 | K7: 45453 | L7: YouTube | M7: 7478 | X7: 45453 | Z7: 141896
A8: 45453 | B8: Twitter | C8: 5225 | D8: 291 | E8: 146830 | F8: =Twitter!$C8-Twitter!$D8 -> 4934 | G8: 0.033603487 | H8: 19.551863 | I8: 44546 | K8: 45453 | M8: 4934 | X8: 45453 | Z8: 146830
A9: 45453 | B9: Twitter | C9: 3978 | D9: 543 | E9: 150265 | F9: =Twitter!$C9-Twitter!$D9 -> 3435 | G9: 0.022859615 | H9: 49.159818 | I9: 34286 | K9: 45453 | M9: 3435 | X9: 45453 | Z9: 150265
A10: 45460 | B10: Instagram | C10: 8373 | D10: 921 | E10: 157717 | F10: =Twitter!$C10-Twitter!$D10 -> 7452 | G10: 0.047249187 | H10: 12.226329 | I10: 15110 | K10: 45460 | L10: Instagram | M10: 7452 | X10: 45460 | Z10: 157717
A11: 45460 | B11: Twitter | C11: 6907 | D11: 834 | E11: 163790 | F11: =Twitter!$C11-Twitter!$D11 -> 6073 | G11: 0.037077966 | H11: 54.158984 | I11: 22087 | K11: 45460 | M11: 6073 | X11: 45460 | Z11: 163790
A12: 45460 | B12: LinkedIn | C12: 7097 | D12: 369 | E12: 170518 | F12: =Twitter!$C12-Twitter!$D12 -> 6728 | G12: 0.039456245 | H12: 9.2506363 | I12: 33762 | K12: 45460 | L12: LinkedIn | M12: 6728 | X12: 45460 | Z12: 170518
A13: 45460 | B13: Instagram | C13: 6656 | D13: 978 | E13: 176196 | F13: =Twitter!$C13-Twitter!$D13 -> 5678 | G13: 0.032225476 | H13: 60.425889 | I13: 27081 | K13: 45460 | L13: Instagram | M13: 5678 | X13: 45460 | Z13: 176196
A14: 45467 | B14: Twitter | C14: 9984 | D14: 1330 | E14: 184850 | F14: =Twitter!$C14-Twitter!$D14 -> 8654 | G14: 0.046816338 | H14: 57.524479 | I14: 44947 | K14: 45467 | M14: 8654 | X14: 45467 | Z14: 184850
A15: 45467 | B15: Instagram | C15: 5259 | D15: 374 | E15: 189735 | F15: =Twitter!$C15-Twitter!$D15 -> 4885 | G15: 0.025746436 | H15: 14.827523 | I15: 19596 | K15: 45467 | L15: Instagram | M15: 4885 | X15: 45467 | Z15: 189735
A16: 45467 | B16: YouTube | C16: 9286 | D16: 633 | E16: 198388 | F16: =Twitter!$C16-Twitter!$D16 -> 8653 | G16: 0.043616549 | H16: 5.4343005 | I16: 48019 | K16: 45467 | L16: YouTube | M16: 8653 | X16: 45467 | Z16: 198388
A17: 45467 | B17: Twitter | C17: 6901 | D17: 471 | E17: 204818 | F17: =Twitter!$C17-Twitter!$D17 -> 6430 | G17: 0.031393725 | H17: 60.827662 | I17: 52003 | K17: 45467 | M17: 6430 | X17: 45467 | Z17: 204818
A18: 45474 | B18: LinkedIn | C18: 5917 | D18: 475 | E18: 210260 | F18: =Twitter!$C18-Twitter!$D18 -> 5442 | G18: 0.025882241 | H18: 17.894036 | I18: 28313 | K18: 45474 | L18: LinkedIn | M18: 5442 | X18: 45474 | Z18: 210260
A19: 45474 | B19: Twitter | C19: 9429 | D19: 966 | E19: 218723 | F19: =Twitter!$C19-Twitter!$D19 -> 8463 | G19: 0.038692776 | H19: 7.6914636 | I19: 57639 | K19: 45474 | M19: 8463 | X19: 45474 | Z19: 218723
A20: 45474 | B20: Instagram | C20: 3530 | D20: 328 | E20: 221925 | F20: =Twitter!$C20-Twitter!$D20 -> 3202 | G20: 0.014428298 | H20: 12.83722 | I20: 11013 | K20: 45474 | L20: Instagram | M20: 3202 | X20: 45474 | Z20: 221925
A21: 45474 | B21: Instagram | C21: 2960 | D21: 234 | E21: 224651 | F21: =Twitter!$C21-Twitter!$D21 -> 2726 | G21: 0.012134377 | H21: 17.412787 | I21: 59378 | K21: 45474 | L21: Instagram | M21: 2726 | X21: 45474 | Z21: 224651
A22: 45481 | B22: Twitter | C22: 8045 | D22: 894 | E22: 231802 | F22: =Twitter!$C22-Twitter!$D22 -> 7151 | G22: 0.030849604 | H22: 47.634188 | I22: 33705 | K22: 45481 | M22: 7151 | X22: 45481 | Z22: 231802
A23: 45481 | B23: LinkedIn | C23: 2048 | D23: 130 | E23: 233720 | F23: =Twitter!$C23-Twitter!$D23 -> 1918 | G23: 0.0082064008 | H23: 39.284614 | I23: 11828 | K23: 45481 | L23: LinkedIn | M23: 1918 | X23: 45481 | Z23: 233720
A24: 45481 | B24: LinkedIn | C24: 6772 | D24: 536 | E24: 239956 | F24: =Twitter!$C24-Twitter!$D24 -> 6236 | G24: 0.025988098 | H24: 9.8205504 | I24: 17909 | K24: 45481 | L24: LinkedIn | M24: 6236 | X24: 45481 | Z24: 239956
A25: 45481 | B25: LinkedIn | C25: 3529 | D25: 305 | E25: 243180 | F25: =Twitter!$C25-Twitter!$D25 -> 3224 | G25: 0.013257669 | H25: 41.606629 | I25: 48356 | K25: 45481 | L25: LinkedIn | M25: 3224 | X25: 45481 | Z25: 243180
A26: 45488 | B26: Instagram | C26: 3964 | D26: 378 | E26: 246766 | F26: =Twitter!$C26-Twitter!$D26 -> 3586 | G26: 0.014531986 | H26: 13.63559 | I26: 23109 | K26: 45488 | L26: Instagram | M26: 3586 | X26: 45488 | Z26: 246766
A27: 45488 | B27: Twitter | C27: 8137 | D27: 1045 | E27: 253858 | F27: =Twitter!$C27-Twitter!$D27 -> 7092 | G27: 0.027936878 | H27: 20.472469 | I27: 12023 | K27: 45488 | M27: 7092 | X27: 45488 | Z27: 253858
A28: 45488 | B28: YouTube | C28: 1963 | D28: 137 | E28: 255684 | F28: =Twitter!$C28-Twitter!$D28 -> 1826 | G28: 0.0071416279 | H28: 11.208367 | I28: 24537 | K28: 45488 | L28: YouTube | M28: 1826 | X28: 45488 | Z28: 255684
A29: 45488 | B29: Instagram | C29: 1536 | D29: 155 | E29: 257065 | F29: =Twitter!$C29-Twitter!$D29 -> 1381 | G29: 0.0053721821 | H29: 12.157626 | I29: 36661 | K29: 45488 | L29: Instagram | M29: 1381 | X29: 45488 | Z29: 257065
A30: 45495 | B30: LinkedIn | C30: 8340 | D30: 911 | E30: 264494 | F30: =Twitter!$C30-Twitter!$D30 -> 7429 | G30: 0.028087594 | H30: 37.302926 | I30: 48659 | K30: 45495 | L30: LinkedIn | M30: 7429 | X30: 45495 | Z30: 264494
A31: 45495 | B31: Twitter | C31: 8179 | D31: 446 | E31: 272227 | F31: =Twitter!$C31-Twitter!$D31 -> 7733 | G31: 0.02840644 | H31: 41.821715 | I31: 43848 | K31: 45495 | M31: 7733 | X31: 45495 | Z31: 272227
A32: 45495 | B32: LinkedIn | C32: 8967 | D32: 993 | E32: 280201 | F32: =Twitter!$C32-Twitter!$D32 -> 7974 | G32: 0.028458143 | H32: 52.792103 | I32: 47804 | K32: 45495 | L32: LinkedIn | M32: 7974 | X32: 45495 | Z32: 280201
A33: 45495 | B33: YouTube | C33: 9734 | D33: 652 | E33: 289283 | F33: =Twitter!$C33-Twitter!$D33 -> 9082 | G33: 0.031394862 | H33: 49.647923 | I33: 25379 | K33: 45495 | L33: YouTube | M33: 9082 | X33: 45495 | Z33: 289283
A34: 45502 | B34: LinkedIn | C34: 1845 | D34: 104 | E34: 291024 | F34: =Twitter!$C34-Twitter!$D34 -> 1741 | G34: 0.0059823245 | H34: 28.158159 | I34: 37766 | K34: 45502 | L34: LinkedIn | M34: 1741 | X34: 45502 | Z34: 291024
A35: 45502 | B35: LinkedIn | C35: 6777 | D35: 981 | E35: 296820 | F35: =Twitter!$C35-Twitter!$D35 -> 5796 | G35: 0.019526986 | H35: 23.920558 | I35: 53590 | K35: 45502 | L35: LinkedIn | M35: 5796 | X35: 45502 | Z35: 296820
A36: 45502 | B36: YouTube | C36: 4036 | D36: 591 | E36: 300265 | F36: =Twitter!$C36-Twitter!$D36 -> 3445 | G36: 0.011473199 | H36: 44.219273 | I36: 12563 | K36: 45502 | L36: YouTube | M36: 3445 | X36: 45502 | Z36: 300265
A37: 45502 | B37: Twitter | C37: 6947 | D37: 908 | E37: 306304 | F37: =Twitter!$C37-Twitter!$D37 -> 6039 | G37: 0.019715707 | H37: 14.117674 | I37: 46060 | K37: 45502 | M37: 6039 | X37: 45502 | Z37: 306304
A38: 45509 | B38: Instagram | C38: 3494 | D38: 281 | E38: 309517 | F38: =Twitter!$C38-Twitter!$D38 -> 3213 | G38: 0.01038069 | H38: 27.765519 | I38: 39197 | K38: 45509 | L38: Instagram | M38: 3213 | X38: 45509 | Z38: 309517
A39: 45509 | B39: Twitter | C39: 3719 | D39: 222 | E39: 313014 | F39: =Twitter!$C39-Twitter!$D39 -> 3497 | G39: 0.011172024 | H39: 21.669318 | I39: 13586 | K39: 45509 | M39: 3497 | X39: 45509 | Z39: 313014
A40: 45509 | B40: YouTube | C40: 2884 | D40: 341 | E40: 315557 | F40: =Twitter!$C40-Twitter!$D40 -> 2543 | G40: 0.0080587659 | H40: 46.99975 | I40: 26087 | K40: 45509 | L40: YouTube | M40: 2543 | X40: 45509 | Z40: 315557
...

Sheet YouTube
A1: Week_Start_Date | B1: Platform | C1: New_Followers | D1: Unfollows | E1: Total_Followers | F1: Net Followers Gain | G1: Follower Growth Rate | H1: Engagement_Rate | I1: Ad_Spend | K1: Week_Start_Date | L1: Column1 | M1: Net Followers Gain | X1: Week_Start_Date | Y1: Column1 | Z1: Total_Followers
A2: 45446 | B2: Instagram | C2: 4138 | D2: 361 | E2: 103777 | F2: =YouTube!$C2-YouTube!$D2 -> 3777 | G2: 0.036395348 | H2: 56.637791 | I2: 23944 | K2: 45446 | L2: Instagram | M2: 3777 | X2: 45446 | Z2: 103777
A3: 45446 | B3: Twitter | C3: 8693 | D3: 1261 | E3: 111209 | F3: =YouTube!$C3-YouTube!$D3 -> 7432 | G3: 0.066829124 | H3: 69.475492 | I3: 29873 | K3: 45446 | L3: Twitter | M3: 7432 | X3: 45446 | Z3: 111209
A4: 45446 | B4: YouTube | C4: 9264 | D4: 1141 | E4: 119332 | F4: =YouTube!$C4-YouTube!$D4 -> 8123 | G4: 0.068070593 | H4: 92.312205 | I4: 50372 | K4: 45446 | M4: 8123 | X4: 45446 | Z4: 119332
A5: 45446 | B5: YouTube | C5: 8842 | D5: 971 | E5: 127203 | F5: =YouTube!$C5-YouTube!$D5 -> 7871 | G5: 0.061877471 | H5: 16.351816 | I5: 33928 | K5: 45446 | M5: 7871 | X5: 45446 | Z5: 127203
A6: 45453 | B6: Instagram | C6: 7721 | D6: 506 | E6: 134418 | F6: =YouTube!$C6-YouTube!$D6 -> 7215 | G6: 0.053675847 | H6: 35.577824 | I6: 25379 | K6: 45453 | L6: Instagram | M6: 7215 | X6: 45453 | Z6: 134418
A7: 45453 | B7: YouTube | C7: 8002 | D7: 524 | E7: 141896 | F7: =YouTube!$C7-YouTube!$D7 -> 7478 | G7: 0.052700569 | H7: 52.064893 | I7: 46751 | K7: 45453 | M7: 7478 | X7: 45453 | Z7: 141896
A8: 45453 | B8: Twitter | C8: 5225 | D8: 291 | E8: 146830 | F8: =YouTube!$C8-YouTube!$D8 -> 4934 | G8: 0.033603487 | H8: 19.551863 | I8: 44546 | K8: 45453 | L8: Twitter | M8: 4934 | X8: 45453 | Z8: 146830
A9: 45453 | B9: Twitter | C9: 3978 | D9: 543 | E9: 150265 | F9: =YouTube!$C9-YouTube!$D9 -> 3435 | G9: 0.022859615 | H9: 49.159818 | I9: 34286 | K9: 45453 | L9: Twitter | M9: 3435 | X9: 45453 | Z9: 150265
A10: 45460 | B10: Instagram | C10: 8373 | D10: 921 | E10: 157717 | F10: =YouTube!$C10-YouTube!$D10 -> 7452 | G10: 0.047249187 | H10: 12.226329 | I10: 15110 | K10: 45460 | L10: Instagram | M10: 7452 | X10: 45460 | Z10: 157717
A11: 45460 | B11: Twitter | C11: 6907 | D11: 834 | E11: 163790 | F11: =YouTube!$C11-YouTube!$D11 -> 6073 | G11: 0.037077966 | H11: 54.158984 | I11: 22087 | K11: 45460 | L11: Twitter | M11: 6073 | X11: 45460 | Z11: 163790
A12: 45460 | B12: LinkedIn | C12: 7097 | D12: 369 | E12: 170518 | F12: =YouTube!$C12-YouTube!$D12 -> 6728 | G12: 0.039456245 | H12: 9.2506363 | I12: 33762 | K12: 45460 | L12: LinkedIn | M12: 6728 | X12: 45460 | Z12: 170518
A13: 45460 | B13: Instagram | C13: 6656 | D13: 978 | E13: 176196 | F13: =YouTube!$C13-YouTube!$D13 -> 5678 | G13: 0.032225476 | H13: 60.425889 | I13: 27081 | K13: 45460 | L13: Instagram | M13: 5678 | X13: 45460 | Z13: 176196
A14: 45467 | B14: Twitter | C14: 9984 | D14: 1330 | E14: 184850 | F14: =YouTube!$C14-YouTube!$D14 -> 8654 | G14: 0.046816338 | H14: 57.524479 | I14: 44947 | K14: 45467 | L14: Twitter | M14: 8654 | X14: 45467 | Z14: 184850
A15: 45467 | B15: Instagram | C15: 5259 | D15: 374 | E15: 189735 | F15: =YouTube!$C15-YouTube!$D15 -> 4885 | G15: 0.025746436 | H15: 14.827523 | I15: 19596 | K15: 45467 | L15: Instagram | M15: 4885 | X15: 45467 | Z15: 189735
A16: 45467 | B16: YouTube | C16: 9286 | D16: 633 | E16: 198388 | F16: =YouTube!$C16-YouTube!$D16 -> 8653 | G16: 0.043616549 | H16: 5.4343005 | I16: 48019 | K16: 45467 | M16: 8653 | X16: 45467 | Z16: 198388
A17: 45467 | B17: Twitter | C17: 6901 | D17: 471 | E17: 204818 | F17: =YouTube!$C17-YouTube!$D17 -> 6430 | G17: 0.031393725 | H17: 60.827662 | I17: 52003 | K17: 45467 | L17: Twitter | M17: 6430 | X17: 45467 | Z17: 204818
A18: 45474 | B18: LinkedIn | C18: 5917 | D18: 475 | E18: 210260 | F18: =YouTube!$C18-YouTube!$D18 -> 5442 | G18: 0.025882241 | H18: 17.894036 | I18: 28313 | K18: 45474 | L18: LinkedIn | M18: 5442 | X18: 45474 | Z18: 210260
A19: 45474 | B19: Twitter | C19: 9429 | D19: 966 | E19: 218723 | F19: =YouTube!$C19-YouTube!$D19 -> 8463 | G19: 0.038692776 | H19: 7.6914636 | I19: 57639 | K19: 45474 | L19: Twitter | M19: 8463 | X19: 45474 | Z19: 218723
A20: 45474 | B20: Instagram | C20: 3530 | D20: 328 | E20: 221925 | F20: =YouTube!$C20-YouTube!$D20 -> 3202 | G20: 0.014428298 | H20: 12.83722 | I20: 11013 | K20: 45474 | L20: Instagram | M20: 3202 | X20: 45474 | Z20: 221925
A21: 45474 | B21: Instagram | C21: 2960 | D21: 234 | E21: 224651 | F21: =YouTube!$C21-YouTube!$D21 -> 2726 | G21: 0.012134377 | H21: 17.412787 | I21: 59378 | K21: 45474 | L21: Instagram | M21: 2726 | X21: 45474 | Z21: 224651
A22: 45481 | B22: Twitter | C22: 8045 | D22: 894 | E22: 231802 | F22: =YouTube!$C22-YouTube!$D22 -> 7151 | G22: 0.030849604 | H22: 47.634188 | I22: 33705 | K22: 45481 | L22: Twitter | M22: 7151 | X22: 45481 | Z22: 231802
A23: 45481 | B23: LinkedIn | C23: 2048 | D23: 130 | E23: 233720 | F23: =YouTube!$C23-YouTube!$D23 -> 1918 | G23: 0.0082064008 | H23: 39.284614 | I23: 11828 | K23: 45481 | L23: LinkedIn | M23: 1918 | X23: 45481 | Z23: 233720
A24: 45481 | B24: LinkedIn | C24: 6772 | D24: 536 | E24: 239956 | F24: =YouTube!$C24-YouTube!$D24 -> 6236 | G24: 0.025988098 | H24: 9.8205504 | I24: 17909 | K24: 45481 | L24: LinkedIn | M24: 6236 | X24: 45481 | Z24: 239956
A25: 45481 | B25: LinkedIn | C25: 3529 | D25: 305 | E25: 243180 | F25: =YouTube!$C25-YouTube!$D25 -> 3224 | G25: 0.013257669 | H25: 41.606629 | I25: 48356 | K25: 45481 | L25: LinkedIn | M25: 3224 | X25: 45481 | Z25: 243180
A26: 45488 | B26: Instagram | C26: 3964 | D26: 378 | E26: 246766 | F26: =YouTube!$C26-YouTube!$D26 -> 3586 | G26: 0.014531986 | H26: 13.63559 | I26: 23109 | K26: 45488 | L26: Instagram | M26: 3586 | X26: 45488 | Z26: 246766
A27: 45488 | B27: Twitter | C27: 8137 | D27: 1045 | E27: 253858 | F27: =YouTube!$C27-YouTube!$D27 -> 7092 | G27: 0.027936878 | H27: 20.472469 | I27: 12023 | K27: 45488 | L27: Twitter | M27: 7092 | X27: 45488 | Z27: 253858
A28: 45488 | B28: YouTube | C28: 1963 | D28: 137 | E28: 255684 | F28: =YouTube!$C28-YouTube!$D28 -> 1826 | G28: 0.0071416279 | H28: 11.208367 | I28: 24537 | K28: 45488 | M28: 1826 | X28: 45488 | Z28: 255684
A29: 45488 | B29: Instagram | C29: 1536 | D29: 155 | E29: 257065 | F29: =YouTube!$C29-YouTube!$D29 -> 1381 | G29: 0.0053721821 | H29: 12.157626 | I29: 36661 | K29: 45488 | L29: Instagram | M29: 1381 | X29: 45488 | Z29: 257065
A30: 45495 | B30: LinkedIn | C30: 8340 | D30: 911 | E30: 264494 | F30: =YouTube!$C30-YouTube!$D30 -> 7429 | G30: 0.028087594 | H30: 37.302926 | I30: 48659 | K30: 45495 | L30: LinkedIn | M30: 7429 | X30: 45495 | Z30: 264494
A31: 45495 | B31: Twitter | C31: 8179 | D31: 446 | E31: 272227 | F31: =YouTube!$C31-YouTube!$D31 -> 7733 | G31: 0.02840644 | H31: 41.821715 | I31: 43848 | K31: 45495 | L31: Twitter | M31: 7733 | X31: 45495 | Z31: 272227
A32: 45495 | B32: LinkedIn | C32: 8967 | D32: 993 | E32: 280201 | F32: =YouTube!$C32-YouTube!$D32 -> 7974 | G32: 0.028458143 | H32: 52.792103 | I32: 47804 | K32: 45495 | L32: LinkedIn | M32: 7974 | X32: 45495 | Z32: 280201
A33: 45495 | B33: YouTube | C33: 9734 | D33: 652 | E33: 289283 | F33: =YouTube!$C33-YouTube!$D33 -> 9082 | G33: 0.031394862 | H33: 49.647923 | I33: 25379 | K33: 45495 | M33: 9082 | X33: 45495 | Z33: 289283
A34: 45502 | B34: LinkedIn | C34: 1845 | D34: 104 | E34: 291024 | F34: =YouTube!$C34-YouTube!$D34 -> 1741 | G34: 0.0059823245 | H34: 28.158159 | I34: 37766 | K34: 45502 | L34: LinkedIn | M34: 1741 | X34: 45502 | Z34: 291024
A35: 45502 | B35: LinkedIn | C35: 6777 | D35: 981 | E35: 296820 | F35: =YouTube!$C35-YouTube!$D35 -> 5796 | G35: 0.019526986 | H35: 23.920558 | I35: 53590 | K35: 45502 | L35: LinkedIn | M35: 5796 | X35: 45502 | Z35: 296820
A36: 45502 | B36: YouTube | C36: 4036 | D36: 591 | E36: 300265 | F36: =YouTube!$C36-YouTube!$D36 -> 3445 | G36: 0.011473199 | H36: 44.219273 | I36: 12563 | K36: 45502 | M36: 3445 | X36: 45502 | Z36: 300265
A37: 45502 | B37: Twitter | C37: 6947 | D37: 908 | E37: 306304 | F37: =YouTube!$C37-YouTube!$D37 -> 6039 | G37: 0.019715707 | H37: 14.117674 | I37: 46060 | K37: 45502 | L37: Twitter | M37: 6039 | X37: 45502 | Z37: 306304
A38: 45509 | B38: Instagram | C38: 3494 | D38: 281 | E38: 309517 | F38: =YouTube!$C38-YouTube!$D38 -> 3213 | G38: 0.01038069 | H38: 27.765519 | I38: 39197 | K38: 45509 | L38: Instagram | M38: 3213 | X38: 45509 | Z38: 309517
A39: 45509 | B39: Twitter | C39: 3719 | D39: 222 | E39: 313014 | F39: =YouTube!$C39-YouTube!$D39 -> 3497 | G39: 0.011172024 | H39: 21.669318 | I39: 13586 | K39: 45509 | L39: Twitter | M39: 3497 | X39: 45509 | Z39: 313014
A40: 45509 | B40: YouTube | C40: 2884 | D40: 341 | E40: 315557 | F40: =YouTube!$C40-YouTube!$D40 -> 2543 | G40: 0.0080587659 | H40: 46.99975 | I40: 26087 | K40: 45509 | M40: 2543 | X40: 45509 | Z40: 315557
...

Sheet LinkdIn
A1: Week_Start_Date | B1: Platform | C1: New_Followers | D1: Unfollows | E1: Total_Followers | F1: Net Followers Gain | G1: Follower Growth Rate | H1: Engagement_Rate | I1: Ad_Spend | K1: Week_Start_Date | L1: Column1 | M1: Net Followers Gain | W1: Week_Start_Date | X1: Column1 | Y1: Total_Followers
A2: 45446 | B2: Instagram | C2: 4138 | D2: 361 | E2: 103777 | F2: =Table4_1416[[#This Row],[New_Followers]]-Table4_1416[[#This Row],[Unfollows]] -> 3777 | G2: 0.036395348 | H2: 56.637791 | I2: 23944 | K2: 45446 | L2: Instagram | M2: 3777 | W2: 45446 | Y2: 103777
A3: 45446 | B3: Twitter | C3: 8693 | D3: 1261 | E3: 111209 | F3: =Table4_1416[[#This Row],[New_Followers]]-Table4_1416[[#This Row],[Unfollows]] -> 7432 | G3: 0.066829124 | H3: 69.475492 | I3: 29873 | K3: 45446 | L3: Twitter | M3: 7432 | W3: 45446 | Y3: 111209
A4: 45446 | B4: YouTube | C4: 9264 | D4: 1141 | E4: 119332 | F4: =Table4_1416[[#This Row],[New_Followers]]-Table4_1416[[#This Row],[Unfollows]] -> 8123 | G4: 0.068070593 | H4: 92.312205 | I4: 50372 | K4: 45446 | L4: YouTube | M4: 8123 | W4: 45446 | Y4: 119332
A5: 45446 | B5: YouTube | C5: 8842 | D5: 971 | E5: 127203 | F5: =Table4_1416[[#This Row],[New_Followers]]-Table4_1416[[#This Row],[Unfollows]] -> 7871 | G5: 0.061877471 | H5: 16.351816 | I5: 33928 | K5: 45446 | L5: YouTube | M5: 7871 | W5: 45446 | Y5: 127203
A6: 45453 | B6: Instagram | C6: 7721 | D6: 506 | E6: 134418 | F6: =Table4_1416[[#This Row],[New_Followers]]-Table4_1416[[#This Row],[Unfollows]] -> 7215 | G6: 0.053675847 | H6: 35.577824 | I6: 25379 | K6: 45453 | L6: Instagram | M6: 7215 | W6: 45453 | Y6: 134418
A7: 45453 | B7: YouTube | C7: 8002 | D7: 524 | E7: 141896 | F7: =Table4_1416[[#This Row],[New_Followers]]-Table4_1416[[#This Row],[Unfollows]] -> 7478 | G7: 0.052700569 | H7: 52.064893 | I7: 46751 | K7: 45453 | L7: YouTube | M7: 7478 | W7: 45453 | Y7: 141896
A8: 45453 | B8: Twitter | C8: 5225 | D8: 291 | E8: 146830 | F8: =Table4_1416[[#This Row],[New_Followers]]-Table4_1416[[#This Row],[Unfollows]] -> 4934 | G8: 0.033603487 | H8: 19.551863 | I8: 44546 | K8: 45453 | L8: Twitter | M8: 4934 | W8: 45453 | Y8: 146830
A9: 45453 | B9: Twitter | C9: 3978 | D9: 543 | E9: 150265 | F9: =Table4_1416[[#This Row],[New_Followers]]-Table4_1416[[#This Row],[Unfollows]] -> 3435 | G9: 0.022859615 | H9: 49.159818 | I9: 34286 | K9: 45453 | L9: Twitter | M9: 3435 | W9: 45453 | Y9: 150265
A10: 45460 | B10: Instagram | C10: 8373 | D10: 921 | E10: 157717 | F10: =Table4_1416[[#This Row],[New_Followers]]-Table4_1416[[#This Row],[Unfollows]] -> 7452 | G10: 0.047249187 | H10: 12.226329 | I10: 15110 | K10: 45460 | L10: Instagram | M10: 7452 | W10: 45460 | Y10: 157717
A11: 45460 | B11: Twitter | C11: 6907 | D11: 834 | E11: 163790 | F11: =Table4_1416[[#This Row],[New_Followers]]-Table4_1416[[#This Row],[Unfollows]] -> 6073 | G11: 0.037077966 | H11: 54.158984 | I11: 22087 | K11: 45460 | L11: Twitter | M11: 6073 | W11: 45460 | Y11: 163790
A12: 45460 | B12: LinkedIn | C12: 7097 | D12: 369 | E12: 170518 | F12: =Table4_1416[[#This Row],[New_Followers]]-Table4_1416[[#This Row],[Unfollows]] -> 6728 | G12: 0.039456245 | H12: 9.2506363 | I12: 33762 | K12: 45460 | M12: 6728 | W12: 45460 | Y12: 170518
A13: 45460 | B13: Instagram | C13: 6656 | D13: 978 | E13: 176196 | F13: =Table4_1416[[#This Row],[New_Followers]]-Table4_1416[[#This Row],[Unfollows]] -> 5678 | G13: 0.032225476 | H13: 60.425889 | I13: 27081 | K13: 45460 | L13: Instagram | M13: 5678 | W13: 45460 | Y13: 176196
A14: 45467 | B14: Twitter | C14: 9984 | D14: 1330 | E14: 184850 | F14: =Table4_1416[[#This Row],[New_Followers]]-Table4_1416[[#This Row],[Unfollows]] -> 8654 | G14: 0.046816338 | H14: 57.524479 | I14: 44947 | K14: 45467 | L14: Twitter | M14: 8654 | W14: 45467 | Y14: 184850
A15: 45467 | B15: Instagram | C15: 5259 | D15: 374 | E15: 189735 | F15: =Table4_1416[[#This Row],[New_Followers]]-Table4_1416[[#This Row],[Unfollows]] -> 4885 | G15: 0.025746436 | H15: 14.827523 | I15: 19596 | K15: 45467 | L15: Instagram | M15: 4885 | W15: 45467 | Y15: 189735
A16: 45467 | B16: YouTube | C16: 9286 | D16: 633 | E16: 198388 | F16: =Table4_1416[[#This Row],[New_Followers]]-Table4_1416[[#This Row],[Unfollows]] -> 8653 | G16: 0.043616549 | H16: 5.4343005 | I16: 48019 | K16: 45467 | L16: YouTube | M16: 8653 | W16: 45467 | Y16: 198388
A17: 45467 | B17: Twitter | C17: 6901 | D17: 471 | E17: 204818 | F17: =Table4_1416[[#This Row],[New_Followers]]-Table4_1416[[#This Row],[Unfollows]] -> 6430 | G17: 0.031393725 | H17: 60.827662 | I17: 52003 | K17: 45467 | L17: Twitter | M17: 6430 | W17: 45467 | Y17: 204818
A18: 45474 | B18: LinkedIn | C18: 5917 | D18: 475 | E18: 210260 | F18: =Table4_1416[[#This Row],[New_Followers]]-Table4_1416[[#This Row],[Unfollows]] -> 5442 | G18: 0.025882241 | H18: 17.894036 | I18: 28313 | K18: 45474 | M18: 5442 | W18: 45474 | Y18: 210260
A19: 45474 | B19: Twitter | C19: 9429 | D19: 966 | E19: 218723 | F19: =Table4_1416[[#This Row],[New_Followers]]-Table4_1416[[#This Row],[Unfollows]] -> 8463 | G19: 0.038692776 | H19: 7.6914636 | I19: 57639 | K19: 45474 | L19: Twitter | M19: 8463 | W19: 45474 | Y19: 218723
A20: 45474 | B20: Instagram | C20: 3530 | D20: 328 | E20: 221925 | F20: =Table4_1416[[#This Row],[New_Followers]]-Table4_1416[[#This Row],[Unfollows]] -> 3202 | G20: 0.014428298 | H20: 12.83722 | I20: 11013 | K20: 45474 | L20: Instagram | M20: 3202 | W20: 45474 | Y20: 221925
A21: 45474 | B21: Instagram | C21: 2960 | D21: 234 | E21: 224651 | F21: =Table4_1416[[#This Row],[New_Followers]]-Table4_1416[[#This Row],[Unfollows]] -> 2726 | G21: 0.012134377 | H21: 17.412787 | I21: 59378 | K21: 45474 | L21: Instagram | M21: 2726 | W21: 45474 | Y21: 224651
A22: 45481 | B22: Twitter | C22: 8045 | D22: 894 | E22: 231802 | F22: =Table4_1416[[#This Row],[New_Followers]]-Table4_1416[[#This Row],[Unfollows]] -> 7151 | G22: 0.030849604 | H22: 47.634188 | I22: 33705 | K22: 45481 | L22: Twitter | M22: 7151 | W22: 45481 | Y22: 231802
A23: 45481 | B23: LinkedIn | C23: 2048 | D23: 130 | E23: 233720 | F23: =Table4_1416[[#This Row],[New_Followers]]-Table4_1416[[#This Row],[Unfollows]] -> 1918 | G23: 0.0082064008 | H23: 39.284614 | I23: 11828 | K23: 45481 | M23: 1918 | W23: 45481 | Y23: 233720
A24: 45481 | B24: LinkedIn | C24: 6772 | D24: 536 | E24: 239956 | F24: =Table4_1416[[#This Row],[New_Followers]]-Table4_1416[[#This Row],[Unfollows]] -> 6236 | G24: 0.025988098 | H24: 9.8205504 | I24: 17909 | K24: 45481 | M24: 6236 | W24: 45481 | Y24: 239956
A25: 45481 | B25: LinkedIn | C25: 3529 | D25: 305 | E25: 243180 | F25: =Table4_1416[[#This Row],[New_Followers]]-Table4_1416[[#This Row],[Unfollows]] -> 3224 | G25: 0.013257669 | H25: 41.606629 | I25: 48356 | K25: 45481 | M25: 3224 | W25: 45481 | Y25: 243180
A26: 45488 | B26: Instagram | C26: 3964 | D26: 378 | E26: 246766 | F26: =Table4_1416[[#This Row],[New_Followers]]-Table4_1416[[#This Row],[Unfollows]] -> 3586 | G26: 0.014531986 | H26: 13.63559 | I26: 23109 | K26: 45488 | L26: Instagram | M26: 3586 | W26: 45488 | Y26: 246766
A27: 45488 | B27: Twitter | C27: 8137 | D27: 1045 | E27: 253858 | F27: =Table4_1416[[#This Row],[New_Followers]]-Table4_1416[[#This Row],[Unfollows]] -> 7092 | G27: 0.027936878 | H27: 20.472469 | I27: 12023 | K27: 45488 | L27: Twitter | M27: 7092 | W27: 45488 | Y27: 253858
A28: 45488 | B28: YouTube | C28: 1963 | D28: 137 | E28: 255684 | F28: =Table4_1416[[#This Row],[New_Followers]]-Table4_1416[[#This Row],[Unfollows]] -> 1826 | G28: 0.0071416279 | H28: 11.208367 | I28: 24537 | K28: 45488 | L28: YouTube | M28: 1826 | W28: 45488 | Y28: 255684
A29: 45488 | B29: Instagram | C29: 1536 | D29: 155 | E29: 257065 | F29: =Table4_1416[[#This Row],[New_Followers]]-Table4_1416[[#This Row],[Unfollows]] -> 1381 | G29: 0.0053721821 | H29: 12.157626 | I29: 36661 | K29: 45488 | L29: Instagram | M29: 1381 | W29: 45488 | Y29: 257065
A30: 45495 | B30: LinkedIn | C30: 8340 | D30: 911 | E30: 264494 | F30: =Table4_1416[[#This Row],[New_Followers]]-Table4_1416[[#This Row],[Unfollows]] -> 7429 | G30: 0.028087594 | H30: 37.302926 | I30: 48659 | K30: 45495 | M30: 7429 | W30: 45495 | Y30: 264494
A31: 45495 | B31: Twitter | C31: 8179 | D31: 446 | E31: 272227 | F31: =Table4_1416[[#This Row],[New_Followers]]-Table4_1416[[#This Row],[Unfollows]] -> 7733 | G31: 0.02840644 | H31: 41.821715 | I31: 43848 | K31: 45495 | L31: Twitter | M31: 7733 | W31: 45495 | Y31: 272227
A32: 45495 | B32: LinkedIn | C32: 8967 | D32: 993 | E32: 280201 | F32: =Table4_1416[[#This Row],[New_Followers]]-Table4_1416[[#This Row],[Unfollows]] -> 7974 | G32: 0.028458143 | H32: 52.792103 | I32: 47804 | K32: 45495 | M32: 7974 | W32: 45495 | Y32: 280201
A33: 45495 | B33: YouTube | C33: 9734 | D33: 652 | E33: 289283 | F33: =Table4_1416[[#This Row],[New_Followers]]-Table4_1416[[#This Row],[Unfollows]] -> 9082 | G33: 0.031394862 | H33: 49.647923 | I33: 25379 | K33: 45495 | L33: YouTube | M33: 9082 | W33: 45495 | Y33: 289283
A34: 45502 | B34: LinkedIn | C34: 1845 | D34: 104 | E34: 291024 | F34: =Table4_1416[[#This Row],[New_Followers]]-Table4_1416[[#This Row],[Unfollows]] -> 1741 | G34: 0.0059823245 | H34: 28.158159 | I34: 37766 | K34: 45502 | M34: 1741 | W34: 45502 | Y34: 291024
A35: 45502 | B35: LinkedIn | C35: 6777 | D35: 981 | E35: 296820 | F35: =Table4_1416[[#This Row],[New_Followers]]-Table4_1416[[#This Row],[Unfollows]] -> 5796 | G35: 0.019526986 | H35: 23.920558 | I35: 53590 | K35: 45502 | M35: 5796 | W35: 45502 | Y35: 296820
A36: 45502 | B36: YouTube | C36: 4036 | D36: 591 | E36: 300265 | F36: =Table4_1416[[#This Row],[New_Followers]]-Table4_1416[[#This Row],[Unfollows]] -> 3445 | G36: 0.011473199 | H36: 44.219273 | I36: 12563 | K36: 45502 | L36: YouTube | M36: 3445 | W36: 45502 | Y36: 300265
A37: 45502 | B37: Twitter | C37: 6947 | D37: 908 | E37: 306304 | F37: =Table4_1416[[#This Row],[New_Followers]]-Table4_1416[[#This Row],[Unfollows]] -> 6039 | G37: 0.019715707 | H37: 14.117674 | I37: 46060 | K37: 45502 | L37: Twitter | M37: 6039 | W37: 45502 | Y37: 306304
A38: 45509 | B38: Instagram | C38: 3494 | D38: 281 | E38: 309517 | F38: =Table4_1416[[#This Row],[New_Followers]]-Table4_1416[[#This Row],[Unfollows]] -> 3213 | G38: 0.01038069 | H38: 27.765519 | I38: 39197 | K38: 45509 | L38: Instagram | M38: 3213 | W38: 45509 | Y38: 309517
A39: 45509 | B39: Twitter | C39: 3719 | D39: 222 | E39: 313014 | F39: =Table4_1416[[#This Row],[New_Followers]]-Table4_1416[[#This Row],[Unfollows]] -> 3497 | G39: 0.011172024 | H39: 21.669318 | I39: 13586 | K39: 45509 | L39: Twitter | M39: 3497 | W39: 45509 | Y39: 313014
A40: 45509 | B40: YouTube | C40: 2884 | D40: 341 | E40: 315557 | F40: =Table4_1416[[#This Row],[New_Followers]]-Table4_1416[[#This Row],[Unfollows]] -> 2543 | G40: 0.0080587659 | H40: 46.99975 | I40: 26087 | K40: 45509 | L40: YouTube | M40: 2543 | W40: 45509 | Y40: 315557
...

Sheet Task 6.3
A1: Week_Start_Date | B1: Platform | C1: New_Followers | D1: Unfollows | E1: Total_Followers | F1: Net Followers Gain | G1: Follower Growth Rate | H1: Engagement_Rate | I1: Ad_Spend | K1: Row Labels | L1: Sum of Total_Followers
A2: 45446 | B2: Instagram | C2: 4138 | D2: 361 | E2: 103777 | F2: =Table4_14[[#This Row],[New_Followers]]-Table4_14[[#This Row],[Unfollows]] -> 3777 | G2: 0.036395348 | H2: 56.637791 | I2: 23944 | K2: 45446 | L2: 246535 | Z2: Task 6: Follower Retention & Loyalty
A3: 45446 | B3: Twitter | C3: 8693 | D3: 1261 | E3: 111209 | F3: =Table4_14[[#This Row],[New_Followers]]-Table4_14[[#This Row],[Unfollows]] -> 7432 | G3: 0.066829124 | H3: 69.475492 | I3: 29873 | K3: 45453 | L3: 141896
A4: 45446 | B4: YouTube | C4: 9264 | D4: 1141 | E4: 119332 | F4: =Table4_14[[#This Row],[New_Followers]]-Table4_14[[#This Row],[Unfollows]] -> 8123 | G4: 0.068070593 | H4: 92.312205 | I4: 50372 | K4: 45467 | L4: 198388 | Z4: 6.3) Use moving averages to smooth growth trends.
A5: 45446 | B5: YouTube | C5: 8842 | D5: 971 | E5: 127203 | F5: =Table4_14[[#This Row],[New_Followers]]-Table4_14[[#This Row],[Unfollows]] -> 7871 | G5: 0.061877471 | H5: 16.351816 | I5: 33928 | K5: 45488 | L5: 255684
A6: 45453 | B6: Instagram | C6: 7721 | D6: 506 | E6: 134418 | F6: =Table4_14[[#This Row],[New_Followers]]-Table4_14[[#This Row],[Unfollows]] -> 7215 | G6: 0.053675847 | H6: 35.577824 | I6: 25379 | K6: 45495 | L6: 289283 | Z6: Using Engagement Dataset
A7: 45453 | B7: YouTube | C7: 8002 | D7: 524 | E7: 141896 | F7: =Table4_14[[#This Row],[New_Followers]]-Table4_14[[#This Row],[Unfollows]] -> 7478 | G7: 0.052700569 | H7: 52.064893 | I7: 46751 | K7: 45502 | L7: 300265 | Z7: Pivot Table --> week start date in rows -->
A8: 45453 | B8: Twitter | C8: 5225 | D8: 291 | E8: 146830 | F8: =Table4_14[[#This Row],[New_Followers]]-Table4_14[[#This Row],[Unfollows]] -> 4934 | G8: 0.033603487 | H8: 19.551863 | I8: 44546 | K8: 45509 | L8: 315557 | Z8: Total followers in values --> sum
A9: 45453 | B9: Twitter | C9: 3978 | D9: 543 | E9: 150265 | F9: =Table4_14[[#This Row],[New_Followers]]-Table4_14[[#This Row],[Unfollows]] -> 3435 | G9: 0.022859615 | H9: 49.159818 | I9: 34286 | K9: 45516 | L9: 340085 | Z9: insert --> line chart -->
A10: 45460 | B10: Instagram | C10: 8373 | D10: 921 | E10: 157717 | F10: =Table4_14[[#This Row],[New_Followers]]-Table4_14[[#This Row],[Unfollows]] -> 7452 | G10: 0.047249187 | H10: 12.226329 | I10: 15110 | K10: 45523 | L10: 729433 | Z10: Chart element --> select axis titles , chart title, grindlines -->
A11: 45460 | B11: Twitter | C11: 6907 | D11: 834 | E11: 163790 | F11: =Table4_14[[#This Row],[New_Followers]]-Table4_14[[#This Row],[Unfollows]] -> 6073 | G11: 0.037077966 | H11: 54.158984 | I11: 22087 | K11: 45530 | L11: 391152 | Z11: Right Click on the line --> Add Trendline
A12: 45460 | B12: LinkedIn | C12: 7097 | D12: 369 | E12: 170518 | F12: =Table4_14[[#This Row],[New_Followers]]-Table4_14[[#This Row],[Unfollows]] -> 6728 | G12: 0.039456245 | H12: 9.2506363 | I12: 33762 | K12: 45544 | L12: 862353 | Z12: Moving Avg --> Period --> 3
A13: 45460 | B13: Instagram | C13: 6656 | D13: 978 | E13: 176196 | F13: =Table4_14[[#This Row],[New_Followers]]-Table4_14[[#This Row],[Unfollows]] -> 5678 | G13: 0.032225476 | H13: 60.425889 | I13: 27081 | K13: 45551 | L13: 895821 | Z13: Power Pivot Analyze --> Inerst slicer --> Platform
A14: 45467 | B14: Twitter | C14: 9984 | D14: 1330 | E14: 184850 | F14: =Table4_14[[#This Row],[New_Followers]]-Table4_14[[#This Row],[Unfollows]] -> 8654 | G14: 0.046816338 | H14: 57.524479 | I14: 44947 | K14: 45572 | L14: 1002177
A15: 45467 | B15: Instagram | C15: 5259 | D15: 374 | E15: 189735 | F15: =Table4_14[[#This Row],[New_Followers]]-Table4_14[[#This Row],[Unfollows]] -> 4885 | G15: 0.025746436 | H15: 14.827523 | I15: 19596 | K15: 45579 | L15: 522852
A16: 45467 | B16: YouTube | C16: 9286 | D16: 633 | E16: 198388 | F16: =Table4_14[[#This Row],[New_Followers]]-Table4_14[[#This Row],[Unfollows]] -> 8653 | G16: 0.043616549 | H16: 5.4343005 | I16: 48019 | K16: 45586 | L16: 545824
A17: 45467 | B17: Twitter | C17: 6901 | D17: 471 | E17: 204818 | F17: =Table4_14[[#This Row],[New_Followers]]-Table4_14[[#This Row],[Unfollows]] -> 6430 | G17: 0.031393725 | H17: 60.827662 | I17: 52003 | K17: 45593 | L17: 1143345
A18: 45474 | B18: LinkedIn | C18: 5917 | D18: 475 | E18: 210260 | F18: =Table4_14[[#This Row],[New_Followers]]-Table4_14[[#This Row],[Unfollows]] -> 5442 | G18: 0.025882241 | H18: 17.894036 | I18: 28313 | K18: 45600 | L18: 599760
A19: 45474 | B19: Twitter | C19: 9429 | D19: 966 | E19: 218723 | F19: =Table4_14[[#This Row],[New_Followers]]-Table4_14[[#This Row],[Unfollows]] -> 8463 | G19: 0.038692776 | H19: 7.6914636 | I19: 57639 | K19: 45607 | L19: 625922
A20: 45474 | B20: Instagram | C20: 3530 | D20: 328 | E20: 221925 | F20: =Table4_14[[#This Row],[New_Followers]]-Table4_14[[#This Row],[Unfollows]] -> 3202 | G20: 0.014428298 | H20: 12.83722 | I20: 11013 | K20: 45621 | L20: 675785
A21: 45474 | B21: Instagram | C21: 2960 | D21: 234 | E21: 224651 | F21: =Table4_14[[#This Row],[New_Followers]]-Table4_14[[#This Row],[Unfollows]] -> 2726 | G21: 0.012134377 | H21: 17.412787 | I21: 59378 | K21: 45628 | L21: 694115
A22: 45481 | B22: Twitter | C22: 8045 | D22: 894 | E22: 231802 | F22: =Table4_14[[#This Row],[New_Followers]]-Table4_14[[#This Row],[Unfollows]] -> 7151 | G22: 0.030849604 | H22: 47.634188 | I22: 33705 | K22: 45635 | L22: 709008
A23: 45481 | B23: LinkedIn | C23: 2048 | D23: 130 | E23: 233720 | F23: =Table4_14[[#This Row],[New_Followers]]-Table4_14[[#This Row],[Unfollows]] -> 1918 | G23: 0.0082064008 | H23: 39.284614 | I23: 11828 | K23: 45649 | L23: 748744
A24: 45481 | B24: LinkedIn | C24: 6772 | D24: 536 | E24: 239956 | F24: =Table4_14[[#This Row],[New_Followers]]-Table4_14[[#This Row],[Unfollows]] -> 6236 | G24: 0.025988098 | H24: 9.8205504 | I24: 17909 | K24: 45663 | L24: 798137
A25: 45481 | B25: LinkedIn | C25: 3529 | D25: 305 | E25: 243180 | F25: =Table4_14[[#This Row],[New_Followers]]-Table4_14[[#This Row],[Unfollows]] -> 3224 | G25: 0.013257669 | H25: 41.606629 | I25: 48356 | K25: 45670 | L25: 818408
... A34: 45502 | B34: LinkedIn | C34: 1845 | D34: 104 | E34: 291024 | F34: =Table4_14[[#This Row],[New_Followers]]-Table4_14[[#This Row],[Unfollows]] -> 1741 | G34: 0.0059823245 | H34: 28.158159 | I34: 37766 | K34: 45782 | L34: 1157985
A35: 45502 | B35: LinkedIn | C35: 6777 | D35: 981 | E35: 296820 | F35: =Table4_14[[#This Row],[New_Followers]]-Table4_14[[#This Row],[Unfollows]] -> 5796 | G35: 0.019526986 | H35: 23.920558 | I35: 53590 | K35: Grand Total | L35: 24658229
A36: 45502 | B36: YouTube | C36: 4036 | D36: 591 | E36: 300265 | F36: =Table4_14[[#This Row],[New_Followers]]-Table4_14[[#This Row],[Unfollows]] -> 3445 | G36: 0.011473199 | H36: 44.219273 | I36: 12563
A37: 45502 | B37: Twitter | C37: 6947 | D37: 908 | E37: 306304 | F37: =Table4_14[[#This Row],[New_Followers]]-Table4_14[[#This Row],[Unfollows]] -> 6039 | G37: 0.019715707 | H37: 14.117674 | I37: 46060
A38: 45509 | B38: Instagram | C38: 3494 | D38: 281 | E38: 309517 | F38: =Table4_14[[#This Row],[New_Followers]]-Table4_14[[#This Row],[Unfollows]] -> 3213 | G38: 0.01038069 | H38: 27.765519 | I38: 39197
A39: 45509 | B39: Twitter | C39: 3719 | D39: 222 | E39: 313014 | F39: =Table4_14[[#This Row],[New_Followers]]-Table4_14[[#This Row],[Unfollows]] -> 3497 | G39: 0.011172024 | H39: 21.669318 | I39: 13586
A40: 45509 | B40: YouTube | C40: 2884 | D40: 341 | E40: 315557 | F40: =Table4_14[[#This Row],[New_Followers]]-Table4_14[[#This Row],[Unfollows]] -> 2543 | G40: 0.0080587659 | H40: 46.99975 | I40: 26087
A41: 45509 | B41: LinkedIn | C41: 5349 | D41: 502 | E41: 320404 | F41: =Table4_14[[#This Row],[New_Followers]]-Table4_14[[#This Row],[Unfollows]] -> 4847 | G41: 0.015127776 | H41: 5.2152907 | I41: 58868
A42: 45516 | B42: Twitter | C42: 6179 | D42: 384 | E42: 326199 | F42: =Table4_14[[#This Row],[New_Followers]]-Table4_14[[#This Row],[Unfollows]] -> 5795 | G42: 0.017765229 | H42: 14.712185 | I42: 33225
A43: 45516 | B43: Instagram | C43: 7610 | D43: 757 | E43: 333052 | F43: =Table4_14[[#This Row],[New_Followers]]-Table4_14[[#This Row],[Unfollows]] -> 6853 | G43: 0.020576366 | H43: 44.450416 | I43: 39750
A44: 45516 | B44: YouTube | C44: 7430 | D44: 397 | E44: 340085 | F44: =Table4_14[[#This Row],[New_Followers]]-Table4_14[[#This Row],[Unfollows]] -> 7033 | G44: 0.020680124 | H44: 28.065043 | I44: 16643
A45: 45516 | B45: Twitter | C45: 8154 | D45: 1149 | E45: 347090 | F45: =Table4_14[[#This Row],[New_Followers]]-Table4_14[[#This Row],[Unfollows]] -> 7005 | G45: 0.020182085 | H45: 26.003918 | I45: 37523
A46: 45523 | B46: Instagram | C46: 7488 | D46: 568 | E46: 354010 | F46: =Table4_14[[#This Row],[New_Followers]]-Table4_14[[#This Row],[Unfollows]] -> 6920 | G46: 0.01954747 | H46: 13.477303 | I46: 46727
A47: 45523 | B47: YouTube | C47: 5737 | D47: 666 | E47: 359081 | F47: =Table4_14[[#This Row],[New_Followers]]-Table4_14[[#This Row],[Unfollows]] -> 5071 | G47: 0.014122162 | H47: 4.6034182 | I47: 21005
... A201: 45789 | B201: Twitter | C201: 8527 | D201: 1091 | E201: 1186398 | F201: =Table4_14[[#This Row],[New_Followers]]-Table4_14[[#This Row],[Unfollows]] -> 7436 | G201: 0.0062677112 | H201: 1.6760817 | I201: 41703

Sheet Task 6.3.
A1: Week_Start_Date | B1: Platform | C1: New_Followers | D1: Unfollows | E1: Total_Followers | F1: Net Followers Gain | G1: Follower Growth Rate | H1: Engagement_Rate | I1: Ad_Spend | K1: Row Labels | L1: Sum of Net Followers Gain
A2: 45446 | B2: Instagram | C2: 4138 | D2: 361 | E2: 103777 | F2: =Table4_145[[#This Row],[New_Followers]]-Table4_145[[#This Row],[Unfollows]] -> 3777 | G2: 0.036395348 | H2: 56.637791 | I2: 23944 | K2: 45446 | L2: 27203 | AA2: Task 6: Follower Retention & Loyalty
A3: 45446 | B3: Twitter | C3: 8693 | D3: 1261 | E3: 111209 | F3: =Table4_145[[#This Row],[New_Followers]]-Table4_145[[#This Row],[Unfollows]] -> 7432 | G3: 0.066829124 | H3: 69.475492 | I3: 29873 | K3: 45453 | L3: 23062
A4: 45446 | B4: YouTube | C4: 9264 | D4: 1141 | E4: 119332 | F4: =Table4_145[[#This Row],[New_Followers]]-Table4_145[[#This Row],[Unfollows]] -> 8123 | G4: 0.068070593 | H4: 92.312205 | I4: 50372 | K4: 45460 | L4: 25931 | AA4: 6.3) Use moving averages to smooth growth trends.
A5: 45446 | B5: YouTube | C5: 8842 | D5: 971 | E5: 127203 | F5: =Table4_145[[#This Row],[New_Followers]]-Table4_145[[#This Row],[Unfollows]] -> 7871 | G5: 0.061877471 | H5: 16.351816 | I5: 33928 | K5: 45467 | L5: 28622
A6: 45453 | B6: Instagram | C6: 7721 | D6: 506 | E6: 134418 | F6: =Table4_145[[#This Row],[New_Followers]]-Table4_145[[#This Row],[Unfollows]] -> 7215 | G6: 0.053675847 | H6: 35.577824 | I6: 25379 | K6: 45474 | L6: 19833 | AA6: Using Engagement Dataset
A7: 45453 | B7: YouTube | C7: 8002 | D7: 524 | E7: 141896 | F7: =Table4_145[[#This Row],[New_Followers]]-Table4_145[[#This Row],[Unfollows]] -> 7478 | G7: 0.052700569 | H7: 52.064893 | I7: 46751 | K7: 45481 | L7: 18529 | AA7: Pivot Table --> week start date in rows -->
A8: 45453 | B8: Twitter | C8: 5225 | D8: 291 | E8: 146830 | F8: =Table4_145[[#This Row],[New_Followers]]-Table4_145[[#This Row],[Unfollows]] -> 4934 | G8: 0.033603487 | H8: 19.551863 | I8: 44546 | K8: 45488 | L8: 13885 | AA8: Net followers Gain in values --> sum
A9: 45453 | B9: Twitter | C9: 3978 | D9: 543 | E9: 150265 | F9: =Table4_145[[#This Row],[New_Followers]]-Table4_145[[#This Row],[Unfollows]] -> 3435 | G9: 0.022859615 | H9: 49.159818 | I9: 34286 | K9: 45495 | L9: 32218 | AA9: insert --> line chart -->
A10: 45460 | B10: Instagram | C10: 8373 | D10: 921 | E10: 157717 | F10: =Table4_145[[#This Row],[New_Followers]]-Table4_145[[#This Row],[Unfollows]] -> 7452 | G10: 0.047249187 | H10: 12.226329 | I10: 15110 | K10: 45502 | L10: 17021 | AA10: Chart element --> select axis titles , chart title, grindlines -->
A11: 45460 | B11: Twitter | C11: 6907 | D11: 834 | E11: 163790 | F11: =Table4_145[[#This Row],[New_Followers]]-Table4_145[[#This Row],[Unfollows]] -> 6073 | G11: 0.037077966 | H11: 54.158984 | I11: 22087 | K11: 45509 | L11: 14100 | AA11: Right Click on the line --> Add Trendline
A12: 45460 | B12: LinkedIn | C12: 7097 | D12: 369 | E12: 170518 | F12: =Table4_145[[#This Row],[New_Followers]]-Table4_145[[#This Row],[Unfollows]] -> 6728 | G12: 0.039456245 | H12: 9.2506363 | I12: 33762 | K12: 45516 | L12: 26686 | AA12: Moving Avg --> Period --> 3
A13: 45460 | B13: Instagram | C13: 6656 | D13: 978 | E13: 176196 | F13: =Table4_145[[#This Row],[New_Followers]]-Table4_145[[#This Row],[Unfollows]] -> 5678 | G13: 0.032225476 | H13: 60.425889 | I13: 27081 | K13: 45523 | L13: 23262 | AA13: Power Pivot Analyze --> Inerst slicer --> Platform
A14: 45467 | B14: Twitter | C14: 9984 | D14: 1330 | E14: 184850 | F14: =Table4_145[[#This Row],[New_Followers]]-Table4_145[[#This Row],[Unfollows]] -> 8654 | G14: 0.046816338 | H14: 57.524479 | I14: 44947 | K14: 45530 | L14: 20800
A15: 45467 | B15: Instagram | C15: 5259 | D15: 374 | E15: 189735 | F15: =Table4_145[[#This Row],[New_Followers]]-Table4_145[[#This Row],[Unfollows]] -> 4885 | G15: 0.025746436 | H15: 14.827523 | I15: 19596 | K15: 45537 | L15: 22217
A16: 45467 | B16: YouTube | C16: 9286 | D16: 633 | E16: 198388 | F16: =Table4_145[[#This Row],[New_Followers]]-Table4_145[[#This Row],[Unfollows]] -> 8653 | G16: 0.043616549 | H16: 5.4343005 | I16: 48019 | K16: 45544 | L16: 25176
A17: 45467 | B17: Twitter | C17: 6901 | D17: 471 | E17: 204818 | F17: =Table4_145[[#This Row],[New_Followers]]-Table4_145[[#This Row],[Unfollows]] -> 6430 | G17: 0.031393725 | H17: 60.827662 | I17: 52003 | K17: 45551 | L17: 15432
